Workbook

Sheet Respostas
A1: RESPOSTAS DO EXERCÍCIO (nível de serviço 95%)
A3: Método 1 – Ponto de Pedido / Quantidade Fixa de Encomenda
A4: Ponto de Pedido | B4: ='1 - Qtde Fixa'!B33 | C4: cocos
A5: Quantidade do Lote (Lote Econômico Q0) | B5: ='1 - Qtde Fixa'!B6 | C5: cocos
A6: Estoque de Segurança | B6: ='1 - Qtde Fixa'!C33 | C6: cocos
A8: Método 2 – Estoque Máximo / Período Fixo de Encomenda
A9: Estoque Máximo | B9: ='2 - Período Fixo'!B42 | C9: cocos
A10: Período Fixo de Encomenda | B10: ='2 - Período Fixo'!B5 | C10: dias
A11: Estoque de Segurança | B11: ='2 - Período Fixo'!C42 | C11: cocos
A14: Método 1: sempre que o estoque (físico + a receber) chegar a 180, pedir 122 cocos.
A15: Método 2: a cada 2 dias, pedir 350 − saldo físico − compras a receber.

Sheet Parâmetros
A1: Parâmetros do exercício (slide 61)
A3: Custo de frete por encomenda (Ce) | B3: 15 | C3: R$
A4: Custo de manter 1 unidade por dia (I) | B4: 0.15 | C4: R$/un/dia
A5: Demanda média diária (D) | B5: 75 | C5: un/dia
A6: Demanda máxima diária | B6: 100 | C6: un/dia
A7: Demanda mínima diária | B7: 51 | C7: un/dia
A8: Tempo médio de reposição (TR) | B8: 1.7 | C8: dias
A9: Tempo de reposição máximo | B9: 2 | C9: dias
A10: Tempo de reposição mínimo | B10: 1 | C10: dias
A11: Dias no mês | B11: 30 | C11: dias
A12: Nível de serviço desejado | B12: 0.95
A14: Demanda média no tempo de reposição | B14: =B5*B8 | C14: un
A15: Demanda máxima no tempo de reposição | B15: =B6*B9 | C15: un

Sheet 1 - Qtde Fixa
A1: MÉTODO 1 – Ponto de Pedido / Quantidade Fixa de Encomenda
A3: PASSO 1 – Lote Econômico (Q0)
A4: Q0 = raiz(2 × D × Ce / I)
A5: Q0 calculado | B5: =SQRT(2*'Parâmetros'!B5*'Parâmetros'!B3/'Parâmetros'!B4)
A6: Q0 adotado (arredondado) | B6: =ROUND(B5,0)
A7: Custo mensal de armazenar estoque de ciclo = Q/2 × I × 30 | B7: =B6/2*'Parâmetros'!B4*'Parâmetros'!B11
A8: Custo mensal de encomendar = (D × 30 / Q) × Ce | B8: ='Parâmetros'!B5*'Parâmetros'!B11/B6*'Parâmetros'!B3
A9: Custo mensal total | B9: =B7+B8
A11: PASSO 2 – Distribuição da demanda no tempo de reposição (100 sorteios da aba Planilha1 do professor)
A12: Classe de | B12: até | C12: Frequência | D12: Prob. (%) | E12: Freq. acum. | F12: Prob. acum. (%) | G12: TR sorteado | H12: Demanda dia 1 | I12: Demanda dia 2 | J12: Demanda no TR
A13: 51 | B13: 60 | C13: =COUNTIFS($J$13:$J$112,">="&A13,$J$13:$J$112,"<="&B13) | D13: =C13/COUNT($J$13:$J$112) | E13: =SUM($C$13:C13) | F13: =E13/COUNT($J$13:$J$112) | G13: 1 | H13: 51 | J13: =H13+N(I13)
A14: 61 | B14: 70 | C14: =COUNTIFS($J$13:$J$112,">="&A14,$J$13:$J$112,"<="&B14) | D14: =C14/COUNT($J$13:$J$112) | E14: =SUM($C$13:C14) | F14: =E14/COUNT($J$13:$J$112) | G14: 1 | H14: 52 | J14: =H14+N(I14)
A15: 71 | B15: 80 | C15: =COUNTIFS($J$13:$J$112,">="&A15,$J$13:$J$112,"<="&B15) | D15: =C15/COUNT($J$13:$J$112) | E15: =SUM($C$13:C15) | F15: =E15/COUNT($J$13:$J$112) | G15: 1 | H15: 52 | J15: =H15+N(I15)
A16: 81 | B16: 90 | C16: =COUNTIFS($J$13:$J$112,">="&A16,$J$13:$J$112,"<="&B16) | D16: =C16/COUNT($J$13:$J$112) | E16: =SUM($C$13:C16) | F16: =E16/COUNT($J$13:$J$112) | G16: 1 | H16: 52 | J16: =H16+N(I16)
A17: 91 | B17: 100 | C17: =COUNTIFS($J$13:$J$112,">="&A17,$J$13:$J$112,"<="&B17) | D17: =C17/COUNT($J$13:$J$112) | E17: =SUM($C$13:C17) | F17: =E17/COUNT($J$13:$J$112) | G17: 1 | H17: 54 | J17: =H17+N(I17)
A18: 101 | B18: 110 | C18: =COUNTIFS($J$13:$J$112,">="&A18,$J$13:$J$112,"<="&B18) | D18: =C18/COUNT($J$13:$J$112) | E18: =SUM($C$13:C18) | F18: =E18/COUNT($J$13:$J$112) | G18: 1 | H18: 54 | J18: =H18+N(I18)
A19: 111 | B19: 120 | C19: =COUNTIFS($J$13:$J$112,">="&A19,$J$13:$J$112,"<="&B19) | D19: =C19/COUNT($J$13:$J$112) | E19: =SUM($C$13:C19) | F19: =E19/COUNT($J$13:$J$112) | G19: 1 | H19: 57 | J19: =H19+N(I19)
A20: 121 | B20: 130 | C20: =COUNTIFS($J$13:$J$112,">="&A20,$J$13:$J$112,"<="&B20) | D20: =C20/COUNT($J$13:$J$112) | E20: =SUM($C$13:C20) | F20: =E20/COUNT($J$13:$J$112) | G20: 1 | H20: 57 | J20: =H20+N(I20)
A21: 131 | B21: 140 | C21: =COUNTIFS($J$13:$J$112,">="&A21,$J$13:$J$112,"<="&B21) | D21: =C21/COUNT($J$13:$J$112) | E21: =SUM($C$13:C21) | F21: =E21/COUNT($J$13:$J$112) | G21: 1 | H21: 57 | J21: =H21+N(I21)
A22: 141 | B22: 150 | C22: =COUNTIFS($J$13:$J$112,">="&A22,$J$13:$J$112,"<="&B22) | D22: =C22/COUNT($J$13:$J$112) | E22: =SUM($C$13:C22) | F22: =E22/COUNT($J$13:$J$112) | G22: 1 | H22: 58 | J22: =H22+N(I22)
A23: 151 | B23: 160 | C23: =COUNTIFS($J$13:$J$112,">="&A23,$J$13:$J$112,"<="&B23) | D23: =C23/COUNT($J$13:$J$112) | E23: =SUM($C$13:C23) | F23: =E23/COUNT($J$13:$J$112) | G23: 1 | H23: 58 | J23: =H23+N(I23)
A24: 161 | B24: 170 | C24: =COUNTIFS($J$13:$J$112,">="&A24,$J$13:$J$112,"<="&B24) | D24: =C24/COUNT($J$13:$J$112) | E24: =SUM($C$13:C24) | F24: =E24/COUNT($J$13:$J$112) | G24: 1 | H24: 61 | J24: =H24+N(I24)
... A27: 191 | B27: 200 | C27: =COUNTIFS($J$13:$J$112,">="&A27,$J$13:$J$112,"<="&B27) | D27: =C27/COUNT($J$13:$J$112) | E27: =SUM($C$13:C27) | F27: =E27/COUNT($J$13:$J$112) | G27: 1 | H27: 64 | J27: =H27+N(I27)
G28: 1 | H28: 65 | J28: =H28+N(I28)
A29: PASSO 3 – Ponto de Pedido e Estoque de Segurança | G29: 1 | H29: 67 | J29: =H29+N(I29)
A30: Demanda média no TR = D × TR médio | B30: ='Parâmetros'!B14 | G30: 1 | H30: 68 | J30: =H30+N(I30)
A31: Nível de serviço | B31: Ponto de Pedido | C31: Estoque de Segurança | D31: Custo mensal do ES (R$) | G31: 1 | H31: 69 | J31: =H31+N(I31)
A32: 1 | B32: =INDEX($B$13:$B$27,MATCH(TRUE,INDEX($F$13:$F$27>=1-1E-9,0),0)) | C32: =B32-$B$30 | D32: =C32*'Parâmetros'!$B$4*'Parâmetros'!$B$11 | G32: 1 | H32: 73 | J32: =H32+N(I32)
A33: 0.95 | B33: =INDEX($B$13:$B$27,MATCH(TRUE,INDEX($F$13:$F$27>=0.95-1E-9,0),0)) | C33: =B33-$B$30 | D33: =C33*'Parâmetros'!$B$4*'Parâmetros'!$B$11 | G33: 1 | H33: 74 | J33: =H33+N(I33)
A34: 0.9 | B34: =INDEX($B$13:$B$27,MATCH(TRUE,INDEX($F$13:$F$27>=0.9-1E-9,0),0)) | C34: =B34-$B$30 | D34: =C34*'Parâmetros'!$B$4*'Parâmetros'!$B$11 | G34: 1 | H34: 78 | J34: =H34+N(I34)
G35: 1 | H35: 78 | J35: =H35+N(I35)
A36: RESPOSTA: pedir 122 cocos sempre que o estoque providenciado (físico + a receber) chegar a 180 cocos (ES = 52,5). | G36: 1 | H36: 78 | J36: =H36+N(I36)
G37: 1 | H37: 81 | J37: =H37+N(I37)
G38: 1 | H38: 83 | J38: =H38+N(I38)
G39: 1 | H39: 83 | J39: =H39+N(I39)
G40: 1 | H40: 85 | J40: =H40+N(I40)
G41: 1 | H41: 87 | J41: =H41+N(I41)
G42: 1 | H42: 88 | J42: =H42+N(I42)
G43: 1 | H43: 88 | J43: =H43+N(I43)
G44: 1 | H44: 88 | J44: =H44+N(I44)
...

Sheet 2 - Período Fixo
A1: MÉTODO 2 – Estoque Máximo / Período Fixo de Encomenda
A3: PASSO 1 – Período ótimo de encomenda
A4: T = Q0 / Demanda média diária | B4: ='1 - Qtde Fixa'!B5/'Parâmetros'!B5
A5: T adotado (dias inteiros) | B5: =ROUND(B4,0)
A7: PASSO 2 – Tempo de cobertura = T + TR
A8: TR = 1 dia (30%) → cobertura (dias) | B8: =B5+1
A9: TR = 2 dias (70%) → cobertura (dias) | B9: =B5+2
A10: Cobertura média = T + TR médio | B10: =B5+'Parâmetros'!B8
A11: Demanda média na cobertura = D × cobertura média | B11: ='Parâmetros'!B5*B10
A13: PASSO 3 – Demanda no tempo de cobertura (100 sorteios: TR 1 dia 30% / 2 dias 70%; demanda diária de 51 a 100)
A14: Classe de | B14: até | C14: Frequência | D14: Prob. (%) | E14: Freq. acum. | F14: Prob. acum. (%) | H14: TR sorteado | I14: Dia 1 | J14: Dia 2 | K14: Dia 3 | L14: Dia 4 | M14: Cobertura (dias) | N14: Demanda na cobertura
A15: 171 | B15: 180 | C15: =COUNTIFS($N$15:$N$114,">="&A15,$N$15:$N$114,"<="&B15) | D15: =C15/COUNT($N$15:$N$114) | E15: =SUM($C$15:C15) | F15: =E15/COUNT($N$15:$N$114) | H15: 2 | I15: 93 | J15: 84 | K15: 93 | L15: 73 | M15: =COUNT(I15:L15) | N15: =SUM(I15:L15)
A16: 181 | B16: 190 | C16: =COUNTIFS($N$15:$N$114,">="&A16,$N$15:$N$114,"<="&B16) | D16: =C16/COUNT($N$15:$N$114) | E16: =SUM($C$15:C16) | F16: =E16/COUNT($N$15:$N$114) | H16: 2 | I16: 51 | J16: 74 | K16: 81 | L16: 68 | M16: =COUNT(I16:L16) | N16: =SUM(I16:L16)
A17: 191 | B17: 200 | C17: =COUNTIFS($N$15:$N$114,">="&A17,$N$15:$N$114,"<="&B17) | D17: =C17/COUNT($N$15:$N$114) | E17: =SUM($C$15:C17) | F17: =E17/COUNT($N$15:$N$114) | H17: 2 | I17: 80 | J17: 95 | K17: 89 | L17: 65 | M17: =COUNT(I17:L17) | N17: =SUM(I17:L17)
A18: 201 | B18: 210 | C18: =COUNTIFS($N$15:$N$114,">="&A18,$N$15:$N$114,"<="&B18) | D18: =C18/COUNT($N$15:$N$114) | E18: =SUM($C$15:C18) | F18: =E18/COUNT($N$15:$N$114) | H18: 2 | I18: 93 | J18: 90 | K18: 60 | L18: 79 | M18: =COUNT(I18:L18) | N18: =SUM(I18:L18)
A19: 211 | B19: 220 | C19: =COUNTIFS($N$15:$N$114,">="&A19,$N$15:$N$114,"<="&B19) | D19: =C19/COUNT($N$15:$N$114) | E19: =SUM($C$15:C19) | F19: =E19/COUNT($N$15:$N$114) | H19: 2 | I19: 72 | J19: 64 | K19: 54 | L19: 87 | M19: =COUNT(I19:L19) | N19: =SUM(I19:L19)
A20: 221 | B20: 230 | C20: =COUNTIFS($N$15:$N$114,">="&A20,$N$15:$N$114,"<="&B20) | D20: =C20/COUNT($N$15:$N$114) | E20: =SUM($C$15:C20) | F20: =E20/COUNT($N$15:$N$114) | H20: 1 | I20: 55 | J20: 83 | K20: 94 | M20: =COUNT(I20:L20) | N20: =SUM(I20:L20)
A21: 231 | B21: 240 | C21: =COUNTIFS($N$15:$N$114,">="&A21,$N$15:$N$114,"<="&B21) | D21: =C21/COUNT($N$15:$N$114) | E21: =SUM($C$15:C21) | F21: =E21/COUNT($N$15:$N$114) | H21: 1 | I21: 94 | J21: 76 | K21: 56 | M21: =COUNT(I21:L21) | N21: =SUM(I21:L21)
A22: 241 | B22: 250 | C22: =COUNTIFS($N$15:$N$114,">="&A22,$N$15:$N$114,"<="&B22) | D22: =C22/COUNT($N$15:$N$114) | E22: =SUM($C$15:C22) | F22: =E22/COUNT($N$15:$N$114) | H22: 2 | I22: 54 | J22: 93 | K22: 83 | L22: 65 | M22: =COUNT(I22:L22) | N22: =SUM(I22:L22)
A23: 251 | B23: 260 | C23: =COUNTIFS($N$15:$N$114,">="&A23,$N$15:$N$114,"<="&B23) | D23: =C23/COUNT($N$15:$N$114) | E23: =SUM($C$15:C23) | F23: =E23/COUNT($N$15:$N$114) | H23: 2 | I23: 78 | J23: 79 | K23: 58 | L23: 93 | M23: =COUNT(I23:L23) | N23: =SUM(I23:L23)
A24: 261 | B24: 270 | C24: =COUNTIFS($N$15:$N$114,">="&A24,$N$15:$N$114,"<="&B24) | D24: =C24/COUNT($N$15:$N$114) | E24: =SUM($C$15:C24) | F24: =E24/COUNT($N$15:$N$114) | H24: 2 | I24: 59 | J24: 85 | K24: 71 | L24: 90 | M24: =COUNT(I24:L24) | N24: =SUM(I24:L24)
A25: 271 | B25: 280 | C25: =COUNTIFS($N$15:$N$114,">="&A25,$N$15:$N$114,"<="&B25) | D25: =C25/COUNT($N$15:$N$114) | E25: =SUM($C$15:C25) | F25: =E25/COUNT($N$15:$N$114) | H25: 2 | I25: 95 | J25: 54 | K25: 86 | L25: 61 | M25: =COUNT(I25:L25) | N25: =SUM(I25:L25)
A26: 281 | B26: 290 | C26: =COUNTIFS($N$15:$N$114,">="&A26,$N$15:$N$114,"<="&B26) | D26: =C26/COUNT($N$15:$N$114) | E26: =SUM($C$15:C26) | F26: =E26/COUNT($N$15:$N$114) | H26: 2 | I26: 56 | J26: 76 | K26: 89 | L26: 77 | M26: =COUNT(I26:L26) | N26: =SUM(I26:L26)
A27: 291 | B27: 300 | C27: =COUNTIFS($N$15:$N$114,">="&A27,$N$15:$N$114,"<="&B27) | D27: =C27/COUNT($N$15:$N$114) | E27: =SUM($C$15:C27) | F27: =E27/COUNT($N$15:$N$114) | H27: 2 | I27: 81 | J27: 81 | K27: 89 | L27: 75 | M27: =COUNT(I27:L27) | N27: =SUM(I27:L27)
A28: 301 | B28: 310 | C28: =COUNTIFS($N$15:$N$114,">="&A28,$N$15:$N$114,"<="&B28) | D28: =C28/COUNT($N$15:$N$114) | E28: =SUM($C$15:C28) | F28: =E28/COUNT($N$15:$N$114) | H28: 2 | I28: 92 | J28: 97 | K28: 56 | L28: 63 | M28: =COUNT(I28:L28) | N28: =SUM(I28:L28)
A29: 311 | B29: 320 | C29: =COUNTIFS($N$15:$N$114,">="&A29,$N$15:$N$114,"<="&B29) | D29: =C29/COUNT($N$15:$N$114) | E29: =SUM($C$15:C29) | F29: =E29/COUNT($N$15:$N$114) | H29: 1 | I29: 93 | J29: 67 | K29: 73 | M29: =COUNT(I29:L29) | N29: =SUM(I29:L29)
A30: 321 | B30: 330 | C30: =COUNTIFS($N$15:$N$114,">="&A30,$N$15:$N$114,"<="&B30) | D30: =C30/COUNT($N$15:$N$114) | E30: =SUM($C$15:C30) | F30: =E30/COUNT($N$15:$N$114) | H30: 1 | I30: 95 | J30: 75 | K30: 94 | M30: =COUNT(I30:L30) | N30: =SUM(I30:L30)
A31: 331 | B31: 340 | C31: =COUNTIFS($N$15:$N$114,">="&A31,$N$15:$N$114,"<="&B31) | D31: =C31/COUNT($N$15:$N$114) | E31: =SUM($C$15:C31) | F31: =E31/COUNT($N$15:$N$114) | H31: 2 | I31: 67 | J31: 66 | K31: 72 | L31: 74 | M31: =COUNT(I31:L31) | N31: =SUM(I31:L31)
A32: 341 | B32: 350 | C32: =COUNTIFS($N$15:$N$114,">="&A32,$N$15:$N$114,"<="&B32) | D32: =C32/COUNT($N$15:$N$114) | E32: =SUM($C$15:C32) | F32: =E32/COUNT($N$15:$N$114) | H32: 2 | I32: 87 | J32: 99 | K32: 83 | L32: 62 | M32: =COUNT(I32:L32) | N32: =SUM(I32:L32)
A33: 351 | B33: 360 | C33: =COUNTIFS($N$15:$N$114,">="&A33,$N$15:$N$114,"<="&B33) | D33: =C33/COUNT($N$15:$N$114) | E33: =SUM($C$15:C33) | F33: =E33/COUNT($N$15:$N$114) | H33: 2 | I33: 78 | J33: 53 | K33: 84 | L33: 52 | M33: =COUNT(I33:L33) | N33: =SUM(I33:L33)
A34: 361 | B34: 370 | C34: =COUNTIFS($N$15:$N$114,">="&A34,$N$15:$N$114,"<="&B34) | D34: =C34/COUNT($N$15:$N$114) | E34: =SUM($C$15:C34) | F34: =E34/COUNT($N$15:$N$114) | H34: 2 | I34: 78 | J34: 53 | K34: 75 | L34: 64 | M34: =COUNT(I34:L34) | N34: =SUM(I34:L34)
A35: 371 | B35: 380 | C35: =COUNTIFS($N$15:$N$114,">="&A35,$N$15:$N$114,"<="&B35) | D35: =C35/COUNT($N$15:$N$114) | E35: =SUM($C$15:C35) | F35: =E35/COUNT($N$15:$N$114) | H35: 1 | I35: 57 | J35: 99 | K35: 86 | M35: =COUNT(I35:L35) | N35: =SUM(I35:L35)
A36: 381 | B36: 390 | C36: =COUNTIFS($N$15:$N$114,">="&A36,$N$15:$N$114,"<="&B36) | D36: =C36/COUNT($N$15:$N$114) | E36: =SUM($C$15:C36) | F36: =E36/COUNT($N$15:$N$114) | H36: 2 | I36: 55 | J36: 95 | K36: 68 | L36: 53 | M36: =COUNT(I36:L36) | N36: =SUM(I36:L36)
A37: 391 | B37: 400 | C37: =COUNTIFS($N$15:$N$114,">="&A37,$N$15:$N$114,"<="&B37) | D37: =C37/COUNT($N$15:$N$114) | E37: =SUM($C$15:C37) | F37: =E37/COUNT($N$15:$N$114) | H37: 2 | I37: 82 | J37: 73 | K37: 89 | L37: 91 | M37: =COUNT(I37:L37) | N37: =SUM(I37:L37)
H38: 1 | I38: 83 | J38: 80 | K38: 74 | M38: =COUNT(I38:L38) | N38: =SUM(I38:L38)
A39: PASSO 4 – Estoque Máximo e Estoque de Segurança | H39: 2 | I39: 69 | J39: 80 | K39: 81 | L39: 95 | M39: =COUNT(I39:L39) | N39: =SUM(I39:L39)
A40: Nível de serviço | B40: Estoque Máximo | C40: Estoque de Segurança | D40: Custo mensal do ES (R$) | H40: 1 | I40: 81 | J40: 66 | K40: 61 | M40: =COUNT(I40:L40) | N40: =SUM(I40:L40)
A41: 1 | B41: =INDEX($B$15:$B$37,MATCH(TRUE,INDEX($F$15:$F$37>=1-1E-9,0),0)) | C41: =B41-$B$11 | D41: =C41*'Parâmetros'!$B$4*'Parâmetros'!$B$11 | H41: 2 | I41: 86 | J41: 74 | K41: 62 | L41: 63 | M41: =COUNT(I41:L41) | N41: =SUM(I41:L41)
A42: 0.95 | B42: =INDEX($B$15:$B$37,MATCH(TRUE,INDEX($F$15:$F$37>=0.95-1E-9,0),0)) | C42: =B42-$B$11 | D42: =C42*'Parâmetros'!$B$4*'Parâmetros'!$B$11 | H42: 1 | I42: 65 | J42: 89 | K42: 51 | M42: =COUNT(I42:L42) | N42: =SUM(I42:L42)
A43: 0.9 | B43: =INDEX($B$15:$B$37,MATCH(TRUE,INDEX($F$15:$F$37>=0.9-1E-9,0),0)) | C43: =B43-$B$11 | D43: =C43*'Parâmetros'!$B$4*'Parâmetros'!$B$11 | H43: 1 | I43: 100 | J43: 72 | K43: 62 | M43: =COUNT(I43:L43) | N43: =SUM(I43:L43)
...
